<robot name="simple_humanoid">

  <!-- Base Link -->
  <link name="base_link">
    <visual>
      <geometry>
        <box size="0.2 0.1 0.3"/>
      </geometry>
      <material name="blue">
        <color rgba="0 0 0.8 1"/>
      </material>
    </visual>
  </link>

  <!-- Head Link connected by a fixed joint to base_link -->
  <link name="head_link">
    <visual>
      <geometry>
        <sphere radius="0.1"/>
      </geometry>
      <material name="red">
        <color rgba="0.8 0 0 1"/>
      </material>
    </visual>
  </link>

  <joint name="base_to_head_joint" type="fixed">
    <parent link="base_link"/>
    <child link="head_link"/>
    <origin xyz="0 0 0.2" rpy="0 0 0"/>
  </joint>

  <!-- Right Arm (simplified) -->
  <link name="right_arm_link">
    <visual>
      <geometry>
        <box size="0.05 0.05 0.2"/>
      </geometry>
      <material name="green">
        <color rgba="0 0.8 0 1"/>
      </material>
    </visual>
  </link>

  <joint name="base_to_right_arm_joint" type="revolute">
    <parent link="base_link"/>
    <child link="right_arm_link"/>
    <origin xyz="0 -0.1 0.1" rpy="0 0 0"/>
    <axis xyz="0 1 0"/>
    <limit lower="-1.57" upper="1.57" effort="100" velocity="100"/>
  </joint>

  <!-- ... (similar structure for left arm, legs, etc.) ... -->

</robot>